Workbook

Sheet Current Inventory
A1: Harvest Hope Community Food Bank | Current Inventory
A2: Quantities update automatically from the Donations Log and Distribution History. Last calculated: June 25, 2026
A4: Item ID | B4: Item Name | C4: Category | D4: Unit | E4: Qty on Hand | F4: Soonest Expiry | G4: Days Until Expiry | H4: Expiry Status | I4: Avg Weekly Demand | J4: Weeks of Supply | K4: Stock Status | L4: Priority
A5: FI012 | B5: Canned Mixed Vegetables | C5: Canned Vegetables | D5: Can (15 oz) | E5: =MAX(0,SUMIFS('Donations Log'!G:G,'Donations Log'!C:C,A5,'Donations Log'!H:H,">="&TODAY())-SUMIF('Distribution History'!E:E,A5,'Distribution History'!I:I)) -> 615 | F5: =IF(E5=0,"",IF(_xlfn.MINIFS('Donations Log'!H:H,'Donations Log'!C:C,A5,'Donations Log'!H:H,">"&TODAY())=0,"",_xlfn.MINIFS('Donations Log'!H:H,'Donations Log'!C:C,A5,'Donations Log'!H:H,">"&TODAY()))) -> 46572 | G5: =IF(F5="","",F5-TODAY()) -> 373 | H5: =IF(E5=0,"OUT OF STOCK",IF(G5="","UNKNOWN",IF(G5<=0,"EXPIRED",IF(G5<=3,"CRITICAL",IF(G5<=7,"WARNING",IF(G5<=30,"NOTICE","OK")))))) -> OK | I5: 8.2 | J5: =IFERROR(IF(I5=0,"N/A",IF(E5=0,"0.0",ROUND(E5/I5,1))),"N/A") -> 75 | K5: =IF(E5=0,"OUT OF STOCK",IF(ISNUMBER(J5),IF(J5<1,"CRITICAL LOW",IF(J5<2,"LOW",IF(J5<4,"ADEQUATE","WELL STOCKED"))),"ADEQUATE")) -> WELL STOCKED | L5: Low
A6: FI035 | B6: Diapers - Size 3-4 | C6: Baby & Infant | D6: Pack (32 ct) | E6: =MAX(0,SUMIFS('Donations Log'!G:G,'Donations Log'!C:C,A6,'Donations Log'!H:H,">="&TODAY())-SUMIF('Distribution History'!E:E,A6,'Distribution History'!I:I)) -> 218 | F6: =IF(E6=0,"",IF(_xlfn.MINIFS('Donations Log'!H:H,'Donations Log'!C:C,A6,'Donations Log'!H:H,">"&TODAY())=0,"",_xlfn.MINIFS('Donations Log'!H:H,'Donations Log'!C:C,A6,'Donations Log'!H:H,">"&TODAY()))) -> 46568 | G6: =IF(F6="","",F6-TODAY()) -> 369 | H6: =IF(E6=0,"OUT OF STOCK",IF(G6="","UNKNOWN",IF(G6<=0,"EXPIRED",IF(G6<=3,"CRITICAL",IF(G6<=7,"WARNING",IF(G6<=30,"NOTICE","OK")))))) -> OK | I6: 1.5 | J6: =IFERROR(IF(I6=0,"N/A",IF(E6=0,"0.0",ROUND(E6/I6,1))),"N/A") -> 145.3 | K6: =IF(E6=0,"OUT OF STOCK",IF(ISNUMBER(J6),IF(J6<1,"CRITICAL LOW",IF(J6<2,"LOW",IF(J6<4,"ADEQUATE","WELL STOCKED"))),"ADEQUATE")) -> WELL STOCKED | L6: High
A7: FI034 | B7: Diapers - Size 1-2 | C7: Baby & Infant | D7: Pack (36 ct) | E7: =MAX(0,SUMIFS('Donations Log'!G:G,'Donations Log'!C:C,A7,'Donations Log'!H:H,">="&TODAY())-SUMIF('Distribution History'!E:E,A7,'Distribution History'!I:I)) -> 297 | F7: =IF(E7=0,"",IF(_xlfn.MINIFS('Donations Log'!H:H,'Donations Log'!C:C,A7,'Donations Log'!H:H,">"&TODAY())=0,"",_xlfn.MINIFS('Donations Log'!H:H,'Donations Log'!C:C,A7,'Donations Log'!H:H,">"&TODAY()))) -> 46489 | G7: =IF(F7="","",F7-TODAY()) -> 290 | H7: =IF(E7=0,"OUT OF STOCK",IF(G7="","UNKNOWN",IF(G7<=0,"EXPIRED",IF(G7<=3,"CRITICAL",IF(G7<=7,"WARNING",IF(G7<=30,"NOTICE","OK")))))) -> OK | I7: 1.8 | J7: =IFERROR(IF(I7=0,"N/A",IF(E7=0,"0.0",ROUND(E7/I7,1))),"N/A") -> 165 | K7: =IF(E7=0,"OUT OF STOCK",IF(ISNUMBER(J7),IF(J7<1,"CRITICAL LOW",IF(J7<2,"LOW",IF(J7<4,"ADEQUATE","WELL STOCKED"))),"ADEQUATE")) -> WELL STOCKED | L7: High
A8: FI013 | B8: Canned Peaches | C8: Canned Fruit | D8: Can (15 oz) | E8: =MAX(0,SUMIFS('Donations Log'!G:G,'Donations Log'!C:C,A8,'Donations Log'!H:H,">="&TODAY())-SUMIF('Distribution History'!E:E,A8,'Distribution History'!I:I)) -> 545 | F8: =IF(E8=0,"",IF(_xlfn.MINIFS('Donations Log'!H:H,'Donations Log'!C:C,A8,'Donations Log'!H:H,">"&TODAY())=0,"",_xlfn.MINIFS('Donations Log'!H:H,'Donations Log'!C:C,A8,'Donations Log'!H:H,">"&TODAY()))) -> 46486 | G8: =IF(F8="","",F8-TODAY()) -> 287 | H8: =IF(E8=0,"OUT OF STOCK",IF(G8="","UNKNOWN",IF(G8<=0,"EXPIRED",IF(G8<=3,"CRITICAL",IF(G8<=7,"WARNING",IF(G8<=30,"NOTICE","OK")))))) -> OK | I8: 5.5 | J8: =IFERROR(IF(I8=0,"N/A",IF(E8=0,"0.0",ROUND(E8/I8,1))),"N/A") -> 99.1 | K8: =IF(E8=0,"OUT OF STOCK",IF(ISNUMBER(J8),IF(J8<1,"CRITICAL LOW",IF(J8<2,"LOW",IF(J8<4,"ADEQUATE","WELL STOCKED"))),"ADEQUATE")) -> WELL STOCKED | L8: Low
A9: FI006 | B9: Canned Chickpeas | C9: Canned Protein | D9: Can (15 oz) | E9: =MAX(0,SUMIFS('Donations Log'!G:G,'Donations Log'!C:C,A9,'Donations Log'!H:H,">="&TODAY())-SUMIF('Distribution History'!E:E,A9,'Distribution History'!I:I)) -> 1382 | F9: =IF(E9=0,"",IF(_xlfn.MINIFS('Donations Log'!H:H,'Donations Log'!C:C,A9,'Donations Log'!H:H,">"&TODAY())=0,"",_xlfn.MINIFS('Donations Log'!H:H,'Donations Log'!C:C,A9,'Donations Log'!H:H,">"&TODAY()))) -> 46436 | G9: =IF(F9="","",F9-TODAY()) -> 237 | H9: =IF(E9=0,"OUT OF STOCK",IF(G9="","UNKNOWN",IF(G9<=0,"EXPIRED",IF(G9<=3,"CRITICAL",IF(G9<=7,"WARNING",IF(G9<=30,"NOTICE","OK")))))) -> OK | I9: 9.9 | J9: =IFERROR(IF(I9=0,"N/A",IF(E9=0,"0.0",ROUND(E9/I9,1))),"N/A") -> 139.6 | K9: =IF(E9=0,"OUT OF STOCK",IF(ISNUMBER(J9),IF(J9<1,"CRITICAL LOW",IF(J9<2,"LOW",IF(J9<4,"ADEQUATE","WELL STOCKED"))),"ADEQUATE")) -> WELL STOCKED | L9: Medium
A10: FI027 | B10: Canned Tomato Soup | C10: Soups & Meals | D10: Can (10.75 oz) | E10: =MAX(0,SUMIFS('Donations Log'!G:G,'Donations Log'!C:C,A10,'Donations Log'!H:H,">="&TODAY())-SUMIF('Distribution History'!E:E,A10,'Distribution History'!I:I)) -> 1120 | F10: =IF(E10=0,"",IF(_xlfn.MINIFS('Donations Log'!H:H,'Donations Log'!C:C,A10,'Donations Log'!H:H,">"&TODAY())=0,"",_xlfn.MINIFS('Donations Log'!H:H,'Donations Log'!C:C,A10,'Donations Log'!H:H,">"&TODAY()))) -> 46433 | G10: =IF(F10="","",F10-TODAY()) -> 234 | H10: =IF(E10=0,"OUT OF STOCK",IF(G10="","UNKNOWN",IF(G10<=0,"EXPIRED",IF(G10<=3,"CRITICAL",IF(G10<=7,"WARNING",IF(G10<=30,"NOTICE","OK")))))) -> OK | I10: 8.1 | J10: =IFERROR(IF(I10=0,"N/A",IF(E10=0,"0.0",ROUND(E10/I10,1))),"N/A") -> 138.3 | K10: =IF(E10=0,"OUT OF STOCK",IF(ISNUMBER(J10),IF(J10<1,"CRITICAL LOW",IF(J10<2,"LOW",IF(J10<4,"ADEQUATE","WELL STOCKED"))),"ADEQUATE")) -> WELL STOCKED | L10: Medium
A11: FI029 | B11: Canned Chili with Beans | C11: Soups & Meals | D11: Can (15 oz) | E11: =MAX(0,SUMIFS('Donations Log'!G:G,'Donations Log'!C:C,A11,'Donations Log'!H:H,">="&TODAY())-SUMIF('Distribution History'!E:E,A11,'Distribution History'!I:I)) -> 1110 | F11: =IF(E11=0,"",IF(_xlfn.MINIFS('Donations Log'!H:H,'Donations Log'!C:C,A11,'Donations Log'!H:H,">"&TODAY())=0,"",_xlfn.MINIFS('Donations Log'!H:H,'Donations Log'!C:C,A11,'Donations Log'!H:H,">"&TODAY()))) -> 46406 | G11: =IF(F11="","",F11-TODAY()) -> 207 | H11: =IF(E11=0,"OUT OF STOCK",IF(G11="","UNKNOWN",IF(G11<=0,"EXPIRED",IF(G11<=3,"CRITICAL",IF(G11<=7,"WARNING",IF(G11<=30,"NOTICE","OK")))))) -> OK | I11: 6.8 | J11: =IFERROR(IF(I11=0,"N/A",IF(E11=0,"0.0",ROUND(E11/I11,1))),"N/A") -> 163.2 | K11: =IF(E11=0,"OUT OF STOCK",IF(ISNUMBER(J11),IF(J11<1,"CRITICAL LOW",IF(J11<2,"LOW",IF(J11<4,"ADEQUATE","WELL STOCKED"))),"ADEQUATE")) -> WELL STOCKED | L11: High
A12: FI003 | B12: Canned Salmon | C12: Canned Protein | D12: Can (14.75 oz) | E12: =MAX(0,SUMIFS('Donations Log'!G:G,'Donations Log'!C:C,A12,'Donations Log'!H:H,">="&TODAY())-SUMIF('Distribution History'!E:E,A12,'Distribution History'!I:I)) -> 1056 | F12: =IF(E12=0,"",IF(_xlfn.MINIFS('Donations Log'!H:H,'Donations Log'!C:C,A12,'Donations Log'!H:H,">"&TODAY())=0,"",_xlfn.MINIFS('Donations Log'!H:H,'Donations Log'!C:C,A12,'Donations Log'!H:H,">"&TODAY()))) -> 46396 | G12: =IF(F12="","",F12-TODAY()) -> 197 | H12: =IF(E12=0,"OUT OF STOCK",IF(G12="","UNKNOWN",IF(G12<=0,"EXPIRED",IF(G12<=3,"CRITICAL",IF(G12<=7,"WARNING",IF(G12<=30,"NOTICE","OK")))))) -> OK | I12: 6.6 | J12: =IFERROR(IF(I12=0,"N/A",IF(E12=0,"0.0",ROUND(E12/I12,1))),"N/A") -> 160 | K12: =IF(E12=0,"OUT OF STOCK",IF(ISNUMBER(J12),IF(J12<1,"CRITICAL LOW",IF(J12<2,"LOW",IF(J12<4,"ADEQUATE","WELL STOCKED"))),"ADEQUATE")) -> WELL STOCKED | L12: High
A13: FI001 | B13: Canned Tuna | C13: Canned Protein | D13: Can (5 oz) | E13: =MAX(0,SUMIFS('Donations Log'!G:G,'Donations Log'!C:C,A13,'Donations Log'!H:H,">="&TODAY())-SUMIF('Distribution History'!E:E,A13,'Distribution History'!I:I)) -> 982 | F13: =IF(E13=0,"",IF(_xlfn.MINIFS('Donations Log'!H:H,'Donations Log'!C:C,A13,'Donations Log'!H:H,">"&TODAY())=0,"",_xlfn.MINIFS('Donations Log'!H:H,'Donations Log'!C:C,A13,'Donations Log'!H:H,">"&TODAY()))) -> 46376 | G13: =IF(F13="","",F13-TODAY()) -> 177 | H13: =IF(E13=0,"OUT OF STOCK",IF(G13="","UNKNOWN",IF(G13<=0,"EXPIRED",IF(G13<=3,"CRITICAL",IF(G13<=7,"WARNING",IF(G13<=30,"NOTICE","OK")))))) -> OK | I13: 8.2 | J13: =IFERROR(IF(I13=0,"N/A",IF(E13=0,"0.0",ROUND(E13/I13,1))),"N/A") -> 119.8 | K13: =IF(E13=0,"OUT OF STOCK",IF(ISNUMBER(J13),IF(J13<1,"CRITICAL LOW",IF(J13<2,"LOW",IF(J13<4,"ADEQUATE","WELL STOCKED"))),"ADEQUATE")) -> WELL STOCKED | L13: High
A14: FI010 | B14: Canned Peas | C14: Canned Vegetables | D14: Can (15 oz) | E14: =MAX(0,SUMIFS('Donations Log'!G:G,'Donations Log'!C:C,A14,'Donations Log'!H:H,">="&TODAY())-SUMIF('Distribution History'!E:E,A14,'Distribution History'!I:I)) -> 1224 | F14: =IF(E14=0,"",IF(_xlfn.MINIFS('Donations Log'!H:H,'Donations Log'!C:C,A14,'Donations Log'!H:H,">"&TODAY())=0,"",_xlfn.MINIFS('Donations Log'!H:H,'Donations Log'!C:C,A14,'Donations Log'!H:H,">"&TODAY()))) -> 46357 | G14: =IF(F14="","",F14-TODAY()) -> 158 | H14: =IF(E14=0,"OUT OF STOCK",IF(G14="","UNKNOWN",IF(G14<=0,"EXPIRED",IF(G14<=3,"CRITICAL",IF(G14<=7,"WARNING",IF(G14<=30,"NOTICE","OK")))))) -> OK | I14: 11.6 | J14: =IFERROR(IF(I14=0,"N/A",IF(E14=0,"0.0",ROUND(E14/I14,1))),"N/A") -> 105.5 | K14: =IF(E14=0,"OUT OF STOCK",IF(ISNUMBER(J14),IF(J14<1,"CRITICAL LOW",IF(J14<2,"LOW",IF(J14<4,"ADEQUATE","WELL STOCKED"))),"ADEQUATE")) -> WELL STOCKED | L14: Medium
A15: FI014 | B15: Canned Pears | C15: Canned Fruit | D15: Can (15 oz) | E15: =MAX(0,SUMIFS('Donations Log'!G:G,'Donations Log'!C:C,A15,'Donations Log'!H:H,">="&TODAY())-SUMIF('Distribution History'!E:E,A15,'Distribution History'!I:I)) -> 735 | F15: =IF(E15=0,"",IF(_xlfn.MINIFS('Donations Log'!H:H,'Donations Log'!C:C,A15,'Donations Log'!H:H,">"&TODAY())=0,"",_xlfn.MINIFS('Donations Log'!H:H,'Donations Log'!C:C,A15,'Donations Log'!H:H,">"&TODAY()))) -> 46353 | G15: =IF(F15="","",F15-TODAY()) -> 154 | H15: =IF(E15=0,"OUT OF STOCK",IF(G15="","UNKNOWN",IF(G15<=0,"EXPIRED",IF(G15<=3,"CRITICAL",IF(G15<=7,"WARNING",IF(G15<=30,"NOTICE","OK")))))) -> OK | I15: 3.4 | J15: =IFERROR(IF(I15=0,"N/A",IF(E15=0,"0.0",ROUND(E15/I15,1))),"N/A") -> 216.2 | K15: =IF(E15=0,"OUT OF STOCK",IF(ISNUMBER(J15),IF(J15<1,"CRITICAL LOW",IF(J15<2,"LOW",IF(J15<4,"ADEQUATE","WELL STOCKED"))),"ADEQUATE")) -> WELL STOCKED | L15: Low
A16: FI015 | B16: Canned Mandarin Oranges | C16: Canned Fruit | D16: Can (11 oz) | E16: =MAX(0,SUMIFS('Donations Log'!G:G,'Donations Log'!C:C,A16,'Donations Log'!H:H,">="&TODAY())-SUMIF('Distribution History'!E:E,A16,'Distribution History'!I:I)) -> 725 | F16: =IF(E16=0,"",IF(_xlfn.MINIFS('Donations Log'!H:H,'Donations Log'!C:C,A16,'Donations Log'!H:H,">"&TODAY())=0,"",_xlfn.MINIFS('Donations Log'!H:H,'Donations Log'!C:C,A16,'Donations Log'!H:H,">"&TODAY()))) -> 46350 | G16: =IF(F16="","",F16-TODAY()) -> 151 | H16: =IF(E16=0,"OUT OF STOCK",IF(G16="","UNKNOWN",IF(G16<=0,"EXPIRED",IF(G16<=3,"CRITICAL",IF(G16<=7,"WARNING",IF(G16<=30,"NOTICE","OK")))))) -> OK | I16: 4.7 | J16: =IFERROR(IF(I16=0,"N/A",IF(E16=0,"0.0",ROUND(E16/I16,1))),"N/A") -> 154.3 | K16: =IF(E16=0,"OUT OF STOCK",IF(ISNUMBER(J16),IF(J16<1,"CRITICAL LOW",IF(J16<2,"LOW",IF(J16<4,"ADEQUATE","WELL STOCKED"))),"ADEQUATE")) -> WELL STOCKED | L16: Low
... A54: FI042 | B54: Apples | C54: Fresh Produce | D54: Bag (3 lb) | E54: =MAX(0,SUMIFS('Donations Log'!G:G,'Donations Log'!C:C,A54,'Donations Log'!H:H,">="&TODAY())-SUMIF('Distribution History'!E:E,A54,'Distribution History'!I:I)) -> 0 | F54: =IF(E54=0,"",IF(_xlfn.MINIFS('Donations Log'!H:H,'Donations Log'!C:C,A54,'Donations Log'!H:H,">"&TODAY())=0,"",_xlfn.MINIFS('Donations Log'!H:H,'Donations Log'!C:C,A54,'Donations Log'!H:H,">"&TODAY()))) | G54: =IF(F54="","",F54-TODAY()) | H54: =IF(E54=0,"OUT OF STOCK",IF(G54="","UNKNOWN",IF(G54<=0,"EXPIRED",IF(G54<=3,"CRITICAL",IF(G54<=7,"WARNING",IF(G54<=30,"NOTICE","OK")))))) -> OUT OF STOCK | I54: 1.9 | J54: =IFERROR(IF(I54=0,"N/A",IF(E54=0,"0.0",ROUND(E54/I54,1))),"N/A") -> 0.0 | K54: =IF(E54=0,"OUT OF STOCK",IF(ISNUMBER(J54),IF(J54<1,"CRITICAL LOW",IF(J54<2,"LOW",IF(J54<4,"ADEQUATE","WELL STOCKED"))),"ADEQUATE")) -> OUT OF STOCK | L54: Medium

Sheet AI Recommendations
A1: Harvest Hope Community Food Bank | AI Distribution Recommendations
A2: Auto-calculated from Current Inventory and Demand Weights. Sort by Priority Score (col K) to see most urgent items. Refreshes whenever inventory changes.
A4: Item ID | B4: Item Name | C4: Category | D4: Priority | E4: Qty on Hand | F4: Soonest Expiry | G4: Days Until Expiry | H4: Expiry Status | I4: Best Pantry | J4: Suggested Qty | K4: Priority Score | L4: Recommended Action
A5: FI001 | B5: Canned Tuna | C5: Canned Protein | D5: High | E5: ='Current Inventory'!E5 -> 615 | F5: ='Current Inventory'!F5 -> 46572 | G5: ='Current Inventory'!G5 -> 373 | H5: ='Current Inventory'!H5 -> OK | I5: =IFERROR(VLOOKUP(C5,'Demand Weights'!$A:$G,7,0),"Any pantry") -> St. Augustine's Shelter Pantry | J5: =IFERROR(MIN(E5,MAX(5,ROUND('Current Inventory'!I5*IFERROR(VLOOKUP(C5,'Demand Weights'!$A:$H,8,0),0.5)*1.5,0))),0) -> 12 | K5: =ROUND(0.4*(IF(G5="",5,IF(G5<=3,100,IF(G5<=7,75,IF(G5<=14,50,IF(G5<=30,25,5))))))+0.35*(IFERROR(VLOOKUP(C5,'Demand Weights'!$A:$H,8,0)*100,50))+0.25*(IF(E5=0,100,IF(ISNUMBER('Current Inventory'!J5),IF('Current Inventory'!J5<1,100,IF('Current Inventory'!J5<2,75,IF('Current Inventory'!J5<4,40,5))),5))),0) -> 37 | L5: =IF(E5=0,"No stock available",IF(G5<=3,"URGENT - Distribute TODAY",IF(G5<=7,"HIGH - Distribute this week",IF(K5>=70,"PRIORITY - High demand match",IF(H5="CRITICAL LOW","RESTOCK - Low supply alert","STANDARD - Distribute when ready"))))) -> STANDARD - Distribute when ready
A6: FI002 | B6: Canned Chicken | C6: Canned Protein | D6: High | E6: ='Current Inventory'!E6 -> 218 | F6: ='Current Inventory'!F6 -> 46568 | G6: ='Current Inventory'!G6 -> 369 | H6: ='Current Inventory'!H6 -> OK | I6: =IFERROR(VLOOKUP(C6,'Demand Weights'!$A:$G,7,0),"Any pantry") -> St. Augustine's Shelter Pantry | J6: =IFERROR(MIN(E6,MAX(5,ROUND('Current Inventory'!I6*IFERROR(VLOOKUP(C6,'Demand Weights'!$A:$H,8,0),0.5)*1.5,0))),0) -> 5 | K6: =ROUND(0.4*(IF(G6="",5,IF(G6<=3,100,IF(G6<=7,75,IF(G6<=14,50,IF(G6<=30,25,5))))))+0.35*(IFERROR(VLOOKUP(C6,'Demand Weights'!$A:$H,8,0)*100,50))+0.25*(IF(E6=0,100,IF(ISNUMBER('Current Inventory'!J6),IF('Current Inventory'!J6<1,100,IF('Current Inventory'!J6<2,75,IF('Current Inventory'!J6<4,40,5))),5))),0) -> 37 | L6: =IF(E6=0,"No stock available",IF(G6<=3,"URGENT - Distribute TODAY",IF(G6<=7,"HIGH - Distribute this week",IF(K6>=70,"PRIORITY - High demand match",IF(H6="CRITICAL LOW","RESTOCK - Low supply alert","STANDARD - Distribute when ready"))))) -> STANDARD - Distribute when ready
A7: FI003 | B7: Canned Salmon | C7: Canned Protein | D7: High | E7: ='Current Inventory'!E7 -> 297 | F7: ='Current Inventory'!F7 -> 46489 | G7: ='Current Inventory'!G7 -> 290 | H7: ='Current Inventory'!H7 -> OK | I7: =IFERROR(VLOOKUP(C7,'Demand Weights'!$A:$G,7,0),"Any pantry") -> St. Augustine's Shelter Pantry | J7: =IFERROR(MIN(E7,MAX(5,ROUND('Current Inventory'!I7*IFERROR(VLOOKUP(C7,'Demand Weights'!$A:$H,8,0),0.5)*1.5,0))),0) -> 5 | K7: =ROUND(0.4*(IF(G7="",5,IF(G7<=3,100,IF(G7<=7,75,IF(G7<=14,50,IF(G7<=30,25,5))))))+0.35*(IFERROR(VLOOKUP(C7,'Demand Weights'!$A:$H,8,0)*100,50))+0.25*(IF(E7=0,100,IF(ISNUMBER('Current Inventory'!J7),IF('Current Inventory'!J7<1,100,IF('Current Inventory'!J7<2,75,IF('Current Inventory'!J7<4,40,5))),5))),0) -> 37 | L7: =IF(E7=0,"No stock available",IF(G7<=3,"URGENT - Distribute TODAY",IF(G7<=7,"HIGH - Distribute this week",IF(K7>=70,"PRIORITY - High demand match",IF(H7="CRITICAL LOW","RESTOCK - Low supply alert","STANDARD - Distribute when ready"))))) -> STANDARD - Distribute when ready
A8: FI004 | B8: Canned Black Beans | C8: Canned Protein | D8: High | E8: ='Current Inventory'!E8 -> 545 | F8: ='Current Inventory'!F8 -> 46486 | G8: ='Current Inventory'!G8 -> 287 | H8: ='Current Inventory'!H8 -> OK | I8: =IFERROR(VLOOKUP(C8,'Demand Weights'!$A:$G,7,0),"Any pantry") -> St. Augustine's Shelter Pantry | J8: =IFERROR(MIN(E8,MAX(5,ROUND('Current Inventory'!I8*IFERROR(VLOOKUP(C8,'Demand Weights'!$A:$H,8,0),0.5)*1.5,0))),0) -> 8 | K8: =ROUND(0.4*(IF(G8="",5,IF(G8<=3,100,IF(G8<=7,75,IF(G8<=14,50,IF(G8<=30,25,5))))))+0.35*(IFERROR(VLOOKUP(C8,'Demand Weights'!$A:$H,8,0)*100,50))+0.25*(IF(E8=0,100,IF(ISNUMBER('Current Inventory'!J8),IF('Current Inventory'!J8<1,100,IF('Current Inventory'!J8<2,75,IF('Current Inventory'!J8<4,40,5))),5))),0) -> 37 | L8: =IF(E8=0,"No stock available",IF(G8<=3,"URGENT - Distribute TODAY",IF(G8<=7,"HIGH - Distribute this week",IF(K8>=70,"PRIORITY - High demand match",IF(H8="CRITICAL LOW","RESTOCK - Low supply alert","STANDARD - Distribute when ready"))))) -> STANDARD - Distribute when ready
A9: FI005 | B9: Canned Kidney Beans | C9: Canned Protein | D9: Medium | E9: ='Current Inventory'!E9 -> 1382 | F9: ='Current Inventory'!F9 -> 46436 | G9: ='Current Inventory'!G9 -> 237 | H9: ='Current Inventory'!H9 -> OK | I9: =IFERROR(VLOOKUP(C9,'Demand Weights'!$A:$G,7,0),"Any pantry") -> St. Augustine's Shelter Pantry | J9: =IFERROR(MIN(E9,MAX(5,ROUND('Current Inventory'!I9*IFERROR(VLOOKUP(C9,'Demand Weights'!$A:$H,8,0),0.5)*1.5,0))),0) -> 14 | K9: =ROUND(0.4*(IF(G9="",5,IF(G9<=3,100,IF(G9<=7,75,IF(G9<=14,50,IF(G9<=30,25,5))))))+0.35*(IFERROR(VLOOKUP(C9,'Demand Weights'!$A:$H,8,0)*100,50))+0.25*(IF(E9=0,100,IF(ISNUMBER('Current Inventory'!J9),IF('Current Inventory'!J9<1,100,IF('Current Inventory'!J9<2,75,IF('Current Inventory'!J9<4,40,5))),5))),0) -> 37 | L9: =IF(E9=0,"No stock available",IF(G9<=3,"URGENT - Distribute TODAY",IF(G9<=7,"HIGH - Distribute this week",IF(K9>=70,"PRIORITY - High demand match",IF(H9="CRITICAL LOW","RESTOCK - Low supply alert","STANDARD - Distribute when ready"))))) -> STANDARD - Distribute when ready
A10: FI006 | B10: Canned Chickpeas | C10: Canned Protein | D10: Medium | E10: ='Current Inventory'!E10 -> 1120 | F10: ='Current Inventory'!F10 -> 46433 | G10: ='Current Inventory'!G10 -> 234 | H10: ='Current Inventory'!H10 -> OK | I10: =IFERROR(VLOOKUP(C10,'Demand Weights'!$A:$G,7,0),"Any pantry") -> St. Augustine's Shelter Pantry | J10: =IFERROR(MIN(E10,MAX(5,ROUND('Current Inventory'!I10*IFERROR(VLOOKUP(C10,'Demand Weights'!$A:$H,8,0),0.5)*1.5,0))),0) -> 12 | K10: =ROUND(0.4*(IF(G10="",5,IF(G10<=3,100,IF(G10<=7,75,IF(G10<=14,50,IF(G10<=30,25,5))))))+0.35*(IFERROR(VLOOKUP(C10,'Demand Weights'!$A:$H,8,0)*100,50))+0.25*(IF(E10=0,100,IF(ISNUMBER('Current Inventory'!J10),IF('Current Inventory'!J10<1,100,IF('Current Inventory'!J10<2,75,IF('Current Inventory'!J10<4,40,5))),5))),0) -> 37 | L10: =IF(E10=0,"No stock available",IF(G10<=3,"URGENT - Distribute TODAY",IF(G10<=7,"HIGH - Distribute this week",IF(K10>=70,"PRIORITY - High demand match",IF(H10="CRITICAL LOW","RESTOCK - Low supply alert","STANDARD - Distribute when ready"))))) -> STANDARD - Distribute when ready
A11: FI007 | B11: Peanut Butter | C11: Canned Protein | D11: High | E11: ='Current Inventory'!E11 -> 1110 | F11: ='Current Inventory'!F11 -> 46406 | G11: ='Current Inventory'!G11 -> 207 | H11: ='Current Inventory'!H11 -> OK | I11: =IFERROR(VLOOKUP(C11,'Demand Weights'!$A:$G,7,0),"Any pantry") -> St. Augustine's Shelter Pantry | J11: =IFERROR(MIN(E11,MAX(5,ROUND('Current Inventory'!I11*IFERROR(VLOOKUP(C11,'Demand Weights'!$A:$H,8,0),0.5)*1.5,0))),0) -> 10 | K11: =ROUND(0.4*(IF(G11="",5,IF(G11<=3,100,IF(G11<=7,75,IF(G11<=14,50,IF(G11<=30,25,5))))))+0.35*(IFERROR(VLOOKUP(C11,'Demand Weights'!$A:$H,8,0)*100,50))+0.25*(IF(E11=0,100,IF(ISNUMBER('Current Inventory'!J11),IF('Current Inventory'!J11<1,100,IF('Current Inventory'!J11<2,75,IF('Current Inventory'!J11<4,40,5))),5))),0) -> 37 | L11: =IF(E11=0,"No stock available",IF(G11<=3,"URGENT - Distribute TODAY",IF(G11<=7,"HIGH - Distribute this week",IF(K11>=70,"PRIORITY - High demand match",IF(H11="CRITICAL LOW","RESTOCK - Low supply alert","STANDARD - Distribute when ready"))))) -> STANDARD - Distribute when ready
A12: FI008 | B12: Canned Corn | C12: Canned Vegetables | D12: Medium | E12: ='Current Inventory'!E12 -> 1056 | F12: ='Current Inventory'!F12 -> 46396 | G12: ='Current Inventory'!G12 -> 197 | H12: ='Current Inventory'!H12 -> OK | I12: =IFERROR(VLOOKUP(C12,'Demand Weights'!$A:$G,7,0),"Any pantry") -> Maplewood Senior Center | J12: =IFERROR(MIN(E12,MAX(5,ROUND('Current Inventory'!I12*IFERROR(VLOOKUP(C12,'Demand Weights'!$A:$H,8,0),0.5)*1.5,0))),0) -> 9 | K12: =ROUND(0.4*(IF(G12="",5,IF(G12<=3,100,IF(G12<=7,75,IF(G12<=14,50,IF(G12<=30,25,5))))))+0.35*(IFERROR(VLOOKUP(C12,'Demand Weights'!$A:$H,8,0)*100,50))+0.25*(IF(E12=0,100,IF(ISNUMBER('Current Inventory'!J12),IF('Current Inventory'!J12<1,100,IF('Current Inventory'!J12<2,75,IF('Current Inventory'!J12<4,40,5))),5))),0) -> 35 | L12: =IF(E12=0,"No stock available",IF(G12<=3,"URGENT - Distribute TODAY",IF(G12<=7,"HIGH - Distribute this week",IF(K12>=70,"PRIORITY - High demand match",IF(H12="CRITICAL LOW","RESTOCK - Low supply alert","STANDARD - Distribute when ready"))))) -> STANDARD - Distribute when ready
A13: FI009 | B13: Canned Green Beans | C13: Canned Vegetables | D13: Medium | E13: ='Current Inventory'!E13 -> 982 | F13: ='Current Inventory'!F13 -> 46376 | G13: ='Current Inventory'!G13 -> 177 | H13: ='Current Inventory'!H13 -> OK | I13: =IFERROR(VLOOKUP(C13,'Demand Weights'!$A:$G,7,0),"Any pantry") -> Maplewood Senior Center | J13: =IFERROR(MIN(E13,MAX(5,ROUND('Current Inventory'!I13*IFERROR(VLOOKUP(C13,'Demand Weights'!$A:$H,8,0),0.5)*1.5,0))),0) -> 11 | K13: =ROUND(0.4*(IF(G13="",5,IF(G13<=3,100,IF(G13<=7,75,IF(G13<=14,50,IF(G13<=30,25,5))))))+0.35*(IFERROR(VLOOKUP(C13,'Demand Weights'!$A:$H,8,0)*100,50))+0.25*(IF(E13=0,100,IF(ISNUMBER('Current Inventory'!J13),IF('Current Inventory'!J13<1,100,IF('Current Inventory'!J13<2,75,IF('Current Inventory'!J13<4,40,5))),5))),0) -> 35 | L13: =IF(E13=0,"No stock available",IF(G13<=3,"URGENT - Distribute TODAY",IF(G13<=7,"HIGH - Distribute this week",IF(K13>=70,"PRIORITY - High demand match",IF(H13="CRITICAL LOW","RESTOCK - Low supply alert","STANDARD - Distribute when ready"))))) -> STANDARD - Distribute when ready
A14: FI010 | B14: Canned Peas | C14: Canned Vegetables | D14: Medium | E14: ='Current Inventory'!E14 -> 1224 | F14: ='Current Inventory'!F14 -> 46357 | G14: ='Current Inventory'!G14 -> 158 | H14: ='Current Inventory'!H14 -> OK | I14: =IFERROR(VLOOKUP(C14,'Demand Weights'!$A:$G,7,0),"Any pantry") -> Maplewood Senior Center | J14: =IFERROR(MIN(E14,MAX(5,ROUND('Current Inventory'!I14*IFERROR(VLOOKUP(C14,'Demand Weights'!$A:$H,8,0),0.5)*1.5,0))),0) -> 16 | K14: =ROUND(0.4*(IF(G14="",5,IF(G14<=3,100,IF(G14<=7,75,IF(G14<=14,50,IF(G14<=30,25,5))))))+0.35*(IFERROR(VLOOKUP(C14,'Demand Weights'!$A:$H,8,0)*100,50))+0.25*(IF(E14=0,100,IF(ISNUMBER('Current Inventory'!J14),IF('Current Inventory'!J14<1,100,IF('Current Inventory'!J14<2,75,IF('Current Inventory'!J14<4,40,5))),5))),0) -> 35 | L14: =IF(E14=0,"No stock available",IF(G14<=3,"URGENT - Distribute TODAY",IF(G14<=7,"HIGH - Distribute this week",IF(K14>=70,"PRIORITY - High demand match",IF(H14="CRITICAL LOW","RESTOCK - Low supply alert","STANDARD - Distribute when ready"))))) -> STANDARD - Distribute when ready
A15: FI011 | B15: Canned Diced Tomatoes | C15: Canned Vegetables | D15: Medium | E15: ='Current Inventory'!E15 -> 735 | F15: ='Current Inventory'!F15 -> 46353 | G15: ='Current Inventory'!G15 -> 154 | H15: ='Current Inventory'!H15 -> OK | I15: =IFERROR(VLOOKUP(C15,'Demand Weights'!$A:$G,7,0),"Any pantry") -> Maplewood Senior Center | J15: =IFERROR(MIN(E15,MAX(5,ROUND('Current Inventory'!I15*IFERROR(VLOOKUP(C15,'Demand Weights'!$A:$H,8,0),0.5)*1.5,0))),0) -> 5 | K15: =ROUND(0.4*(IF(G15="",5,IF(G15<=3,100,IF(G15<=7,75,IF(G15<=14,50,IF(G15<=30,25,5))))))+0.35*(IFERROR(VLOOKUP(C15,'Demand Weights'!$A:$H,8,0)*100,50))+0.25*(IF(E15=0,100,IF(ISNUMBER('Current Inventory'!J15),IF('Current Inventory'!J15<1,100,IF('Current Inventory'!J15<2,75,IF('Current Inventory'!J15<4,40,5))),5))),0) -> 35 | L15: =IF(E15=0,"No stock available",IF(G15<=3,"URGENT - Distribute TODAY",IF(G15<=7,"HIGH - Distribute this week",IF(K15>=70,"PRIORITY - High demand match",IF(H15="CRITICAL LOW","RESTOCK - Low supply alert","STANDARD - Distribute when ready"))))) -> STANDARD - Distribute when ready
A16: FI012 | B16: Canned Mixed Vegetables | C16: Canned Vegetables | D16: Low | E16: ='Current Inventory'!E16 -> 725 | F16: ='Current Inventory'!F16 -> 46350 | G16: ='Current Inventory'!G16 -> 151 | H16: ='Current Inventory'!H16 -> OK | I16: =IFERROR(VLOOKUP(C16,'Demand Weights'!$A:$G,7,0),"Any pantry") -> Maplewood Senior Center | J16: =IFERROR(MIN(E16,MAX(5,ROUND('Current Inventory'!I16*IFERROR(VLOOKUP(C16,'Demand Weights'!$A:$H,8,0),0.5)*1.5,0))),0) -> 6 | K16: =ROUND(0.4*(IF(G16="",5,IF(G16<=3,100,IF(G16<=7,75,IF(G16<=14,50,IF(G16<=30,25,5))))))+0.35*(IFERROR(VLOOKUP(C16,'Demand Weights'!$A:$H,8,0)*100,50))+0.25*(IF(E16=0,100,IF(ISNUMBER('Current Inventory'!J16),IF('Current Inventory'!J16<1,100,IF('Current Inventory'!J16<2,75,IF('Current Inventory'!J16<4,40,5))),5))),0) -> 35 | L16: =IF(E16=0,"No stock available",IF(G16<=3,"URGENT - Distribute TODAY",IF(G16<=7,"HIGH - Distribute this week",IF(K16>=70,"PRIORITY - High demand match",IF(H16="CRITICAL LOW","RESTOCK - Low supply alert","STANDARD - Distribute when ready"))))) -> STANDARD - Distribute when ready
... A54: FI050 | B54: Pasta Sauce | C54: Pantry Staples | D54: Medium | E54: ='Current Inventory'!E54 -> 0 | F54: ='Current Inventory'!F54 | G54: ='Current Inventory'!G54 | H54: ='Current Inventory'!H54 -> OUT OF STOCK | I54: =IFERROR(VLOOKUP(C54,'Demand Weights'!$A:$G,7,0),"Any pantry") -> Riverside Community Pantry | J54: =IFERROR(MIN(E54,MAX(5,ROUND('Current Inventory'!I54*IFERROR(VLOOKUP(C54,'Demand Weights'!$A:$H,8,0),0.5)*1.5,0))),0) -> 0 | K54: =ROUND(0.4*(IF(G54="",5,IF(G54<=3,100,IF(G54<=7,75,IF(G54<=14,50,IF(G54<=30,25,5))))))+0.35*(IFERROR(VLOOKUP(C54,'Demand Weights'!$A:$H,8,0)*100,50))+0.25*(IF(E54=0,100,IF(ISNUMBER('Current Inventory'!J54),IF('Current Inventory'!J54<1,100,IF('Current Inventory'!J54<2,75,IF('Current Inventory'!J54<4,40,5))),5))),0) -> 55 | L54: =IF(E54=0,"No stock available",IF(G54<=3,"URGENT - Distribute TODAY",IF(G54<=7,"HIGH - Distribute this week",IF(K54>=70,"PRIORITY - High demand match",IF(H54="CRITICAL LOW","RESTOCK - Low supply alert","STANDARD - Distribute when ready"))))) -> No stock available

Sheet Donations Log
A1: Harvest Hope Community Food Bank | Donations Log
A2: To log a new donation: enter Date (col B), Item ID (col C), Qty Received (col G), Expiration Date (col H), and Donor Type (col K). Other fields fill automatically.
A4: Donation ID | B4: Date | C4: Item ID | D4: Item Name | E4: Category | F4: Unit | G4: Qty Received | H4: Expiration Date | I4: Days Until Expiry | J4: Expiry Status | K4: Donor Type | L4: Notes
A5: =IF(G5="","","DON-"&TEXT(ROW()-4,"0000")) -> DON-0001 | B5: 45833 | C5: FI048 | D5: Orange Juice (64 oz) | E5: Beverages | F5: Bottle (64 oz) | G5: 9 | H5: 45838 | I5: =IF(H5="","",H5-TODAY()) -> -361 | J5: =IF(I5="","",IF(I5<=0,"EXPIRED",IF(I5<=3,"CRITICAL",IF(I5<=7,"WARNING",IF(I5<=30,"NOTICE","OK"))))) -> EXPIRED | K5: School Drive
A6: =IF(G6="","","DON-"&TEXT(ROW()-4,"0000")) -> DON-0002 | B6: 45833 | C6: FI007 | D6: Peanut Butter | E6: Canned Protein | F6: Jar (16 oz) | G6: 37 | H6: 46083 | I6: =IF(H6="","",H6-TODAY()) -> -116 | J6: =IF(I6="","",IF(I6<=0,"EXPIRED",IF(I6<=3,"CRITICAL",IF(I6<=7,"WARNING",IF(I6<=30,"NOTICE","OK"))))) -> EXPIRED | K6: School Drive
A7: =IF(G7="","","DON-"&TEXT(ROW()-4,"0000")) -> DON-0003 | B7: 45833 | C7: FI009 | D7: Canned Green Beans | E7: Canned Vegetables | F7: Can (14.5 oz) | G7: 40 | H7: 46630 | I7: =IF(H7="","",H7-TODAY()) -> 431 | J7: =IF(I7="","",IF(I7<=0,"EXPIRED",IF(I7<=3,"CRITICAL",IF(I7<=7,"WARNING",IF(I7<=30,"NOTICE","OK"))))) -> OK | K7: School Drive
A8: =IF(G8="","","DON-"&TEXT(ROW()-4,"0000")) -> DON-0004 | B8: 45833 | C8: FI015 | D8: Canned Mandarin Oranges | E8: Canned Fruit | F8: Can (11 oz) | G8: 52 | H8: 46756 | I8: =IF(H8="","",H8-TODAY()) -> 557 | J8: =IF(I8="","",IF(I8<=0,"EXPIRED",IF(I8<=3,"CRITICAL",IF(I8<=7,"WARNING",IF(I8<=30,"NOTICE","OK"))))) -> OK | K8: School Drive
A9: =IF(G9="","","DON-"&TEXT(ROW()-4,"0000")) -> DON-0005 | B9: 45837 | C9: FI042 | D9: Apples | E9: Fresh Produce | F9: Bag (3 lb) | G9: 39 | H9: 45846 | I9: =IF(H9="","",H9-TODAY()) -> -353 | J9: =IF(I9="","",IF(I9<=0,"EXPIRED",IF(I9<=3,"CRITICAL",IF(I9<=7,"WARNING",IF(I9<=30,"NOTICE","OK"))))) -> EXPIRED | K9: Corporate Drive
A10: =IF(G10="","","DON-"&TEXT(ROW()-4,"0000")) -> DON-0006 | B10: 45837 | C10: FI046 | D10: Yellow Onions (3 lb) | E10: Fresh Produce | F10: Bag (3 lb) | G10: 41 | H10: 45847 | I10: =IF(H10="","",H10-TODAY()) -> -352 | J10: =IF(I10="","",IF(I10<=0,"EXPIRED",IF(I10<=3,"CRITICAL",IF(I10<=7,"WARNING",IF(I10<=30,"NOTICE","OK"))))) -> EXPIRED | K10: Corporate Drive
A11: =IF(G11="","","DON-"&TEXT(ROW()-4,"0000")) -> DON-0007 | B11: 45837 | C11: FI045 | D11: Potatoes (5 lb) | E11: Fresh Produce | F11: Bag (5 lb) | G11: 37 | H11: 45878 | I11: =IF(H11="","",H11-TODAY()) -> -321 | J11: =IF(I11="","",IF(I11<=0,"EXPIRED",IF(I11<=3,"CRITICAL",IF(I11<=7,"WARNING",IF(I11<=30,"NOTICE","OK"))))) -> EXPIRED | K11: Corporate Drive
A12: =IF(G12="","","DON-"&TEXT(ROW()-4,"0000")) -> DON-0008 | B12: 45837 | C12: FI013 | D12: Canned Peaches | E12: Canned Fruit | F12: Can (15 oz) | G12: 42 | H12: 46486 | I12: =IF(H12="","",H12-TODAY()) -> 287 | J12: =IF(I12="","",IF(I12<=0,"EXPIRED",IF(I12<=3,"CRITICAL",IF(I12<=7,"WARNING",IF(I12<=30,"NOTICE","OK"))))) -> OK | K12: Corporate Drive
A13: =IF(G13="","","DON-"&TEXT(ROW()-4,"0000")) -> DON-0009 | B13: 45837 | C13: FI027 | D13: Canned Tomato Soup | E13: Soups & Meals | F13: Can (10.75 oz) | G13: 72 | H13: 46546 | I13: =IF(H13="","",H13-TODAY()) -> 347 | J13: =IF(I13="","",IF(I13<=0,"EXPIRED",IF(I13<=3,"CRITICAL",IF(I13<=7,"WARNING",IF(I13<=30,"NOTICE","OK"))))) -> OK | K13: Corporate Drive
A14: =IF(G14="","","DON-"&TEXT(ROW()-4,"0000")) -> DON-0010 | B14: 45837 | C14: FI015 | D14: Canned Mandarin Oranges | E14: Canned Fruit | F14: Can (11 oz) | G14: 26 | H14: 46591 | I14: =IF(H14="","",H14-TODAY()) -> 392 | J14: =IF(I14="","",IF(I14<=0,"EXPIRED",IF(I14<=3,"CRITICAL",IF(I14<=7,"WARNING",IF(I14<=30,"NOTICE","OK"))))) -> OK | K14: Corporate Drive
A15: =IF(G15="","","DON-"&TEXT(ROW()-4,"0000")) -> DON-0011 | B15: 45837 | C15: FI035 | D15: Diapers - Size 3-4 | E15: Baby & Infant | F15: Pack (32 ct) | G15: 10 | H15: 46885 | I15: =IF(H15="","",H15-TODAY()) -> 686 | J15: =IF(I15="","",IF(I15<=0,"EXPIRED",IF(I15<=3,"CRITICAL",IF(I15<=7,"WARNING",IF(I15<=30,"NOTICE","OK"))))) -> OK | K15: Corporate Drive
A16: =IF(G16="","","DON-"&TEXT(ROW()-4,"0000")) -> DON-0012 | B16: 45840 | C16: FI041 | D16: Flour Tortillas | E16: Bread & Bakery | F16: Pack (20 ct) | G16: 30 | H16: 45870 | I16: =IF(H16="","",H16-TODAY()) -> -329 | J16: =IF(I16="","",IF(I16<=0,"EXPIRED",IF(I16<=3,"CRITICAL",IF(I16<=7,"WARNING",IF(I16<=30,"NOTICE","OK"))))) -> EXPIRED | K16: Government Surplus
... A1003: =IF(G1003="","","DON-"&TEXT(ROW()-4,"0000")) -> DON-0999 | B1003: 46191 | C1003: FI034 | D1003: Diapers - Size 1-2 | E1003: Baby & Infant | F1003: Pack (36 ct) | G1003: 14 | H1003: 47834 | I1003: =IF(H1003="","",H1003-TODAY()) -> 1635 | J1003: =IF(I1003="","",IF(I1003<=0,"EXPIRED",IF(I1003<=3,"CRITICAL",IF(I1003<=7,"WARNING",IF(I1003<=30,"NOTICE","OK"))))) -> OK | K1003: School Drive
A1004: =IF(G1004="","","DON-"&TEXT(ROW()-4,"0000")) -> DON-1000 | B1004: 46198 | C1004: FI024 | D1004: =IF(C1004="","",IFERROR(VLOOKUP(C1004,'Food Catalog'!$A:$B,2,0),"Unknown")) -> Pancake Mix | E1004: =IF(C1004="","",IFERROR(VLOOKUP(C1004,'Food Catalog'!$A:$C,3,0),"")) -> Breakfast | F1004: =IF(C1004="","",IFERROR(VLOOKUP(C1004,'Food Catalog'!$A:$D,4,0),"")) -> Box (32 oz) | G1004: 4 | H1004: 46199 | I1004: =IF(H1004="","",H1004-TODAY()) -> 0 | J1004: =IF(I1004="","",IF(I1004<=0,"EXPIRED",IF(I1004<=3,"CRITICAL",IF(I1004<=7,"WARNING",IF(I1004<=30,"NOTICE","OK"))))) -> EXPIRED | K1004: Individual Donor
A1005: =IF(G1005="","","DON-"&TEXT(ROW()-4,"0000")) -> DON-1001 | B1005: 46198 | C1005: FI043 | D1005: Bananas | E1005: Fresh Produce | F1005: Bunch (~7) | G1005: 15 | H1005: 46199 | I1005: =IF(H1005="","",H1005-TODAY()) -> 0 | J1005: =IF(I1005="","",IF(I1005<=0,"EXPIRED",IF(I1005<=3,"CRITICAL",IF(I1005<=7,"WARNING",IF(I1005<=30,"NOTICE","OK"))))) -> EXPIRED | K1005: Restaurant Partner
A1006: =IF(G1006="","","DON-"&TEXT(ROW()-4,"0000")) -> DON-1002 | B1006: 46198 | C1006: FI036 | D1006: Milk (1 gallon) | E1006: Dairy & Refrigerated | F1006: Gallon | G1006: 18 | H1006: 46200 | I1006: =IF(H1006="","",H1006-TODAY()) -> 1 | J1006: =IF(I1006="","",IF(I1006<=0,"EXPIRED",IF(I1006<=3,"CRITICAL",IF(I1006<=7,"WARNING",IF(I1006<=30,"NOTICE","OK"))))) -> CRITICAL | K1006: Grocery Rescue
A1007: =IF(G1007="","","DON-"&TEXT(ROW()-4,"0000")) -> DON-1003 | B1007: 46198 | C1007: FI040 | D1007: Whole Wheat Bread | E1007: Bread & Bakery | F1007: Loaf | G1007: 20 | H1007: 46202 | I1007: =IF(H1007="","",H1007-TODAY()) -> 3 | J1007: =IF(I1007="","",IF(I1007<=0,"EXPIRED",IF(I1007<=3,"CRITICAL",IF(I1007<=7,"WARNING",IF(I1007<=30,"NOTICE","OK"))))) -> CRITICAL | K1007: Grocery Rescue
A1008: =IF(G1008="","","DON-"&TEXT(ROW()-4,"0000")) -> DON-1004 | B1008: 46198 | C1008: FI048 | D1008: Orange Juice (64 oz) | E1008: Beverages | F1008: Bottle (64 oz) | G1008: 12 | H1008: 46203 | I1008: =IF(H1008="","",H1008-TODAY()) -> 4 | J1008: =IF(I1008="","",IF(I1008<=0,"EXPIRED",IF(I1008<=3,"CRITICAL",IF(I1008<=7,"WARNING",IF(I1008<=30,"NOTICE","OK"))))) -> WARNING | K1008: Grocery Rescue
A1009: =IF(G1009="","","DON-"&TEXT(ROW()-4,"0000")) -> DON-1005 | B1009: 46198 | C1009: FI031 | D1009: Infant Formula (Powder) | E1009: Baby & Infant | F1009: Can (12.4 oz) | G1009: 8 | H1009: 46204 | I1009: =IF(H1009="","",H1009-TODAY()) -> 5 | J1009: =IF(I1009="","",IF(I1009<=0,"EXPIRED",IF(I1009<=3,"CRITICAL",IF(I1009<=7,"WARNING",IF(I1009<=30,"NOTICE","OK"))))) -> WARNING | K1009: Community Drive
A1010: =IF(G1010="","","DON-"&TEXT(ROW()-4,"0000")) -> DON-1006 | B1010: 46198 | C1010: FI037 | D1010: Eggs (1 dozen) | E1010: Dairy & Refrigerated | F1010: Dozen | G1010: 30 | H1010: 46205 | I1010: =IF(H1010="","",H1010-TODAY()) -> 6 | J1010: =IF(I1010="","",IF(I1010<=0,"EXPIRED",IF(I1010<=3,"CRITICAL",IF(I1010<=7,"WARNING",IF(I1010<=30,"NOTICE","OK"))))) -> WARNING | K1010: Individual Donor
A1011: =IF(G1011="","","DON-"&TEXT(ROW()-4,"0000")) -> DON-1007 | B1011: 46198 | C1011: FI044 | D1011: Baby Carrots | E1011: Fresh Produce | F1011: Bag (1 lb) | G1011: 18 | H1011: 46207 | I1011: =IF(H1011="","",H1011-TODAY()) -> 8 | J1011: =IF(I1011="","",IF(I1011<=0,"EXPIRED",IF(I1011<=3,"CRITICAL",IF(I1011<=7,"WARNING",IF(I1011<=30,"NOTICE","OK"))))) -> NOTICE | K1011: Grocery Rescue
A1012: =IF(G1012="","","DON-"&TEXT(ROW()-4,"0000")) -> DON-1008 | B1012: 46198 | C1012: FI025 | D1012: Granola Bars | E1012: Breakfast | F1012: Box (8 bars) | G1012: 35 | H1012: 46209 | I1012: =IF(H1012="","",H1012-TODAY()) -> 10 | J1012: =IF(I1012="","",IF(I1012<=0,"EXPIRED",IF(I1012<=3,"CRITICAL",IF(I1012<=7,"WARNING",IF(I1012<=30,"NOTICE","OK"))))) -> NOTICE | K1012: Corporate Drive
A1013: =IF(G1013="","","DON-"&TEXT(ROW()-4,"0000")) -> DON-1009 | B1013: 46198 | C1013: FI038 | D1013: Cheddar Cheese (block) | E1013: Dairy & Refrigerated | F1013: Block (16 oz) | G1013: 10 | H1013: 46211 | I1013: =IF(H1013="","",H1013-TODAY()) -> 12 | J1013: =IF(I1013="","",IF(I1013<=0,"EXPIRED",IF(I1013<=3,"CRITICAL",IF(I1013<=7,"WARNING",IF(I1013<=30,"NOTICE","OK"))))) -> NOTICE | K1013: Grocery Rescue
A1014: =IF(G1014="","","DON-"&TEXT(ROW()-4,"0000")) -> DON-1010 | B1014: 46198 | C1014: FI011 | D1014: =IF(C1014="","",IFERROR(VLOOKUP(C1014,'Food Catalog'!$A:$B,2,0),"Unknown")) -> Canned Diced Tomatoes | E1014: =IF(C1014="","",IFERROR(VLOOKUP(C1014,'Food Catalog'!$A:$C,3,0),"")) -> Canned Vegetables | F1014: =IF(C1014="","",IFERROR(VLOOKUP(C1014,'Food Catalog'!$A:$D,4,0),"")) -> Can (14.5 oz) | G1014: 5 | H1014: 46563 | I1014: =IF(H1014="","",H1014-TODAY()) -> 364 | J1014: =IF(I1014="","",IF(I1014<=0,"EXPIRED",IF(I1014<=3,"CRITICAL",IF(I1014<=7,"WARNING",IF(I1014<=30,"NOTICE","OK"))))) -> OK | K1014: Church Drive
A1015: =IF(G1015="","","DON-"&TEXT(ROW()-4,"0000")) -> DON-1011 | B1015: 46199 | C1015: FI040 | D1015: Whole Wheat Bread | E1015: Bread & Bakery | F1015: Loaf | G1015: 25 | H1015: 46202 | I1015: =IF(H1015="","",H1015-TODAY()) -> 3 | J1015: =IF(I1015="","",IF(I1015<=0,"EXPIRED",IF(I1015<=3,"CRITICAL",IF(I1015<=7,"WARNING",IF(I1015<=30,"NOTICE","OK"))))) -> CRITICAL | K1015: Grocery Rescue
A1016: =IF(G1016="","","DON-"&TEXT(ROW()-4,"0000")) | D1016: =IF(C1016="","",IFERROR(VLOOKUP(C1016,'Food Catalog'!$A:$B,2,0),"Unknown")) | E1016: =IF(C1016="","",IFERROR(VLOOKUP(C1016,'Food Catalog'!$A:$C,3,0),"")) | F1016: =IF(C1016="","",IFERROR(VLOOKUP(C1016,'Food Catalog'!$A:$D,4,0),"")) | I1016: =IF(H1016="","",H1016-TODAY()) | J1016: =IF(I1016="","",IF(I1016<=0,"EXPIRED",IF(I1016<=3,"CRITICAL",IF(I1016<=7,"WARNING",IF(I1016<=30,"NOTICE","OK")))))
A1017: =IF(G1017="","","DON-"&TEXT(ROW()-4,"0000")) | D1017: =IF(C1017="","",IFERROR(VLOOKUP(C1017,'Food Catalog'!$A:$B,2,0),"Unknown")) | E1017: =IF(C1017="","",IFERROR(VLOOKUP(C1017,'Food Catalog'!$A:$C,3,0),"")) | F1017: =IF(C1017="","",IFERROR(VLOOKUP(C1017,'Food Catalog'!$A:$D,4,0),"")) | I1017: =IF(H1017="","",H1017-TODAY()) | J1017: =IF(I1017="","",IF(I1017<=0,"EXPIRED",IF(I1017<=3,"CRITICAL",IF(I1017<=7,"WARNING",IF(I1017<=30,"NOTICE","OK")))))
A1018: =IF(G1018="","","DON-"&TEXT(ROW()-4,"0000")) | D1018: =IF(C1018="","",IFERROR(VLOOKUP(C1018,'Food Catalog'!$A:$B,2,0),"Unknown")) | E1018: =IF(C1018="","",IFERROR(VLOOKUP(C1018,'Food Catalog'!$A:$C,3,0),"")) | F1018: =IF(C1018="","",IFERROR(VLOOKUP(C1018,'Food Catalog'!$A:$D,4,0),"")) | I1018: =IF(H1018="","",H1018-TODAY()) | J1018: =IF(I1018="","",IF(I1018<=0,"EXPIRED",IF(I1018<=3,"CRITICAL",IF(I1018<=7,"WARNING",IF(I1018<=30,"NOTICE","OK")))))
A1019: =IF(G1019="","","DON-"&TEXT(ROW()-4,"0000")) | D1019: =IF(C1019="","",IFERROR(VLOOKUP(C1019,'Food Catalog'!$A:$B,2,0),"Unknown")) | E1019: =IF(C1019="","",IFERROR(VLOOKUP(C1019,'Food Catalog'!$A:$C,3,0),"")) | F1019: =IF(C1019="","",IFERROR(VLOOKUP(C1019,'Food Catalog'!$A:$D,4,0),"")) | I1019: =IF(H1019="","",H1019-TODAY()) | J1019: =IF(I1019="","",IF(I1019<=0,"EXPIRED",IF(I1019<=3,"CRITICAL",IF(I1019<=7,"WARNING",IF(I1019<=30,"NOTICE","OK")))))
A1020: =IF(G1020="","","DON-"&TEXT(ROW()-4,"0000")) | D1020: =IF(C1020="","",IFERROR(VLOOKUP(C1020,'Food Catalog'!$A:$B,2,0),"Unknown")) | E1020: =IF(C1020="","",IFERROR(VLOOKUP(C1020,'Food Catalog'!$A:$C,3,0),"")) | F1020: =IF(C1020="","",IFERROR(VLOOKUP(C1020,'Food Catalog'!$A:$D,4,0),"")) | I1020: =IF(H1020="","",H1020-TODAY()) | J1020: =IF(I1020="","",IF(I1020<=0,"EXPIRED",IF(I1020<=3,"CRITICAL",IF(I1020<=7,"WARNING",IF(I1020<=30,"NOTICE","OK")))))
A1021: =IF(G1021="","","DON-"&TEXT(ROW()-4,"0000")) | D1021: =IF(C1021="","",IFERROR(VLOOKUP(C1021,'Food Catalog'!$A:$B,2,0),"Unknown")) | E1021: =IF(C1021="","",IFERROR(VLOOKUP(C1021,'Food Catalog'!$A:$C,3,0),"")) | F1021: =IF(C1021="","",IFERROR(VLOOKUP(C1021,'Food Catalog'!$A:$D,4,0),"")) | I1021: =IF(H1021="","",H1021-TODAY()) | J1021: =IF(I1021="","",IF(I1021<=0,"EXPIRED",IF(I1021<=3,"CRITICAL",IF(I1021<=7,"WARNING",IF(I1021<=30,"NOTICE","OK")))))
A1022: =IF(G1022="","","DON-"&TEXT(ROW()-4,"0000")) | D1022: =IF(C1022="","",IFERROR(VLOOKUP(C1022,'Food Catalog'!$A:$B,2,0),"Unknown")) | E1022: =IF(C1022="","",IFERROR(VLOOKUP(C1022,'Food Catalog'!$A:$C,3,0),"")) | F1022: =IF(C1022="","",IFERROR(VLOOKUP(C1022,'Food Catalog'!$A:$D,4,0),"")) | I1022: =IF(H1022="","",H1022-TODAY()) | J1022: =IF(I1022="","",IF(I1022<=0,"EXPIRED",IF(I1022<=3,"CRITICAL",IF(I1022<=7,"WARNING",IF(I1022<=30,"NOTICE","OK")))))
A1023: =IF(G1023="","","DON-"&TEXT(ROW()-4,"0000")) | D1023: =IF(C1023="","",IFERROR(VLOOKUP(C1023,'Food Catalog'!$A:$B,2,0),"Unknown")) | E1023: =IF(C1023="","",IFERROR(VLOOKUP(C1023,'Food Catalog'!$A:$C,3,0),"")) | F1023: =IF(C1023="","",IFERROR(VLOOKUP(C1023,'Food Catalog'!$A:$D,4,0),"")) | I1023: =IF(H1023="","",H1023-TODAY()) | J1023: =IF(I1023="","",IF(I1023<=0,"EXPIRED",IF(I1023<=3,"CRITICAL",IF(I1023<=7,"WARNING",IF(I1023<=30,"NOTICE","OK")))))
A1024: =IF(G1024="","","DON-"&TEXT(ROW()-4,"0000")) | D1024: =IF(C1024="","",IFERROR(VLOOKUP(C1024,'Food Catalog'!$A:$B,2,0),"Unknown")) | E1024: =IF(C1024="","",IFERROR(VLOOKUP(C1024,'Food Catalog'!$A:$C,3,0),"")) | F1024: =IF(C1024="","",IFERROR(VLOOKUP(C1024,'Food Catalog'!$A:$D,4,0),"")) | I1024: =IF(H1024="","",H1024-TODAY()) | J1024: =IF(I1024="","",IF(I1024<=0,"EXPIRED",IF(I1024<=3,"CRITICAL",IF(I1024<=7,"WARNING",IF(I1024<=30,"NOTICE","OK")))))
A1025: =IF(G1025="","","DON-"&TEXT(ROW()-4,"0000")) | D1025: =IF(C1025="","",IFERROR(VLOOKUP(C1025,'Food Catalog'!$A:$B,2,0),"Unknown")) | E1025: =IF(C1025="","",IFERROR(VLOOKUP(C1025,'Food Catalog'!$A:$C,3,0),"")) | F1025: =IF(C1025="","",IFERROR(VLOOKUP(C1025,'Food Catalog'!$A:$D,4,0),"")) | I1025: =IF(H1025="","",H1025-TODAY()) | J1025: =IF(I1025="","",IF(I1025<=0,"EXPIRED",IF(I1025<=3,"CRITICAL",IF(I1025<=7,"WARNING",IF(I1025<=30,"NOTICE","OK")))))
A1026: =IF(G1026="","","DON-"&TEXT(ROW()-4,"0000")) | D1026: =IF(C1026="","",IFERROR(VLOOKUP(C1026,'Food Catalog'!$A:$B,2,0),"Unknown")) | E1026: =IF(C1026="","",IFERROR(VLOOKUP(C1026,'Food Catalog'!$A:$C,3,0),"")) | F1026: =IF(C1026="","",IFERROR(VLOOKUP(C1026,'Food Catalog'!$A:$D,4,0),"")) | I1026: =IF(H1026="","",H1026-TODAY()) | J1026: =IF(I1026="","",IF(I1026<=0,"EXPIRED",IF(I1026<=3,"CRITICAL",IF(I1026<=7,"WARNING",IF(I1026<=30,"NOTICE","OK")))))
A1027: =IF(G1027="","","DON-"&TEXT(ROW()-4,"0000")) | D1027: =IF(C1027="","",IFERROR(VLOOKUP(C1027,'Food Catalog'!$A:$B,2,0),"Unknown")) | E1027: =IF(C1027="","",IFERROR(VLOOKUP(C1027,'Food Catalog'!$A:$C,3,0),"")) | F1027: =IF(C1027="","",IFERROR(VLOOKUP(C1027,'Food Catalog'!$A:$D,4,0),"")) | I1027: =IF(H1027="","",H1027-TODAY()) | J1027: =IF(I1027="","",IF(I1027<=0,"EXPIRED",IF(I1027<=3,"CRITICAL",IF(I1027<=7,"WARNING",IF(I1027<=30,"NOTICE","OK")))))
...

Sheet Distribution History
A1: Harvest Hope Community Food Bank | Distribution History
A2: To log a distribution: enter Date (col B), Pantry ID (col C), Item ID (col E), and Qty Distributed (col I). Other fields fill automatically.
A4: Dist. ID | B4: Date | C4: Pantry ID | D4: Pantry Name | E4: Item ID | F4: Item Name | G4: Category | H4: Unit | I4: Qty Distributed | J4: Notes
A5: DIST-0001 | B5: 45849 | C5: PP001 | D5: Riverside Community Pantry | E5: FI009 | F5: Canned Green Beans | G5: Canned Vegetables | H5: Can (14.5 oz) | I5: 19
A6: DIST-0002 | B6: 45849 | C6: PP001 | D6: Riverside Community Pantry | E6: FI038 | F6: Cheddar Cheese (block) | G6: Dairy & Refrigerated | H6: Block (16 oz) | I6: 6
A7: DIST-0003 | B7: 45849 | C7: PP001 | D7: Riverside Community Pantry | E7: FI007 | F7: Peanut Butter | G7: Canned Protein | H7: Jar (16 oz) | I7: 17
A8: DIST-0004 | B8: 45849 | C8: PP001 | D8: Riverside Community Pantry | E8: FI010 | F8: Canned Peas | G8: Canned Vegetables | H8: Can (15 oz) | I8: 27
A9: DIST-0005 | B9: 45849 | C9: PP001 | D9: Riverside Community Pantry | E9: FI048 | F9: Orange Juice (64 oz) | G9: Beverages | H9: Bottle (64 oz) | I9: 6
A10: DIST-0006 | B10: 45849 | C10: PP001 | D10: Riverside Community Pantry | E10: FI011 | F10: Canned Diced Tomatoes | G10: Canned Vegetables | H10: Can (14.5 oz) | I10: 21
A11: DIST-0007 | B11: 45849 | C11: PP001 | D11: Riverside Community Pantry | E11: FI029 | F11: Canned Chili with Beans | G11: Soups & Meals | H11: Can (15 oz) | I11: 21
A12: DIST-0008 | B12: 45849 | C12: PP001 | D12: Riverside Community Pantry | E12: FI030 | F12: Canned Beef Stew | G12: Soups & Meals | H12: Can (20 oz) | I12: 11
A13: DIST-0009 | B13: 45853 | C13: PP001 | D13: Riverside Community Pantry | E13: FI010 | F13: Canned Peas | G13: Canned Vegetables | H13: Can (15 oz) | I13: 28
A14: DIST-0010 | B14: 45853 | C14: PP001 | D14: Riverside Community Pantry | E14: FI006 | F14: Canned Chickpeas | G14: Canned Protein | H14: Can (15 oz) | I14: 14
A15: DIST-0011 | B15: 45853 | C15: PP001 | D15: Riverside Community Pantry | E15: FI046 | F15: Yellow Onions (3 lb) | G15: Fresh Produce | H15: Bag (3 lb) | I15: 12
A16: DIST-0012 | B16: 45853 | C16: PP001 | D16: Riverside Community Pantry | E16: FI016 | F16: White Rice (5 lb) | G16: Dry Goods | H16: Bag (5 lb) | I16: 18
... A1681: DIST-1677 | B1681: 46193 | C1681: PP002 | D1681: St. Augustine's Shelter Pantry | E1681: FI035 | F1681: Diapers - Size 3-4 | G1681: Baby & Infant | H1681: Pack (32 ct) | I1681: 1
A1682: =IF(I1682="","","DIST-"&TEXT(ROW()-4,"0000")) -> DIST-1678 | B1682: 46198 | C1682: PP003 | D1682: =IF(C1682="","",IFERROR(VLOOKUP(C1682,'Partner Pantries'!$A:$B,2,0),"")) -> Maplewood Senior Center | E1682: FI030 | F1682: =IF(E1682="","",IFERROR(VLOOKUP(E1682,'Food Catalog'!$A:$B,2,0),"")) -> Canned Beef Stew | G1682: =IF(E1682="","",IFERROR(VLOOKUP(E1682,'Food Catalog'!$A:$C,3,0),"")) -> Soups & Meals | H1682: =IF(E1682="","",IFERROR(VLOOKUP(E1682,'Food Catalog'!$A:$D,4,0),"")) -> Can (20 oz) | I1682: 3
A1683: =IF(I1683="","","DIST-"&TEXT(ROW()-4,"0000")) -> DIST-1679 | B1683: 46199 | C1683: PP002 | D1683: =IF(C1683="","",IFERROR(VLOOKUP(C1683,'Partner Pantries'!$A:$B,2,0),"")) -> St. Augustine's Shelter Pantry | E1683: FI050 | F1683: =IF(E1683="","",IFERROR(VLOOKUP(E1683,'Food Catalog'!$A:$B,2,0),"")) -> Pasta Sauce | G1683: =IF(E1683="","",IFERROR(VLOOKUP(E1683,'Food Catalog'!$A:$C,3,0),"")) -> Pantry Staples | H1683: =IF(E1683="","",IFERROR(VLOOKUP(E1683,'Food Catalog'!$A:$D,4,0),"")) -> Jar (24 oz) | I1683: 1
A1684: =IF(I1684="","",TEXT(ROW()-1682,"DIST-0000")) | D1684: =IF(C1684="","",IFERROR(VLOOKUP(C1684,'Partner Pantries'!$A:$B,2,0),"")) | F1684: =IF(E1684="","",IFERROR(VLOOKUP(E1684,'Food Catalog'!$A:$B,2,0),"")) | G1684: =IF(E1684="","",IFERROR(VLOOKUP(E1684,'Food Catalog'!$A:$C,3,0),"")) | H1684: =IF(E1684="","",IFERROR(VLOOKUP(E1684,'Food Catalog'!$A:$D,4,0),""))
A1685: =IF(I1685="","",TEXT(ROW()-1682,"DIST-0000")) | D1685: =IF(C1685="","",IFERROR(VLOOKUP(C1685,'Partner Pantries'!$A:$B,2,0),"")) | F1685: =IF(E1685="","",IFERROR(VLOOKUP(E1685,'Food Catalog'!$A:$B,2,0),"")) | G1685: =IF(E1685="","",IFERROR(VLOOKUP(E1685,'Food Catalog'!$A:$C,3,0),"")) | H1685: =IF(E1685="","",IFERROR(VLOOKUP(E1685,'Food Catalog'!$A:$D,4,0),""))
A1686: =IF(I1686="","",TEXT(ROW()-1682,"DIST-0000")) | D1686: =IF(C1686="","",IFERROR(VLOOKUP(C1686,'Partner Pantries'!$A:$B,2,0),"")) | F1686: =IF(E1686="","",IFERROR(VLOOKUP(E1686,'Food Catalog'!$A:$B,2,0),"")) | G1686: =IF(E1686="","",IFERROR(VLOOKUP(E1686,'Food Catalog'!$A:$C,3,0),"")) | H1686: =IF(E1686="","",IFERROR(VLOOKUP(E1686,'Food Catalog'!$A:$D,4,0),""))
A1687: =IF(I1687="","",TEXT(ROW()-1682,"DIST-0000")) | D1687: =IF(C1687="","",IFERROR(VLOOKUP(C1687,'Partner Pantries'!$A:$B,2,0),"")) | F1687: =IF(E1687="","",IFERROR(VLOOKUP(E1687,'Food Catalog'!$A:$B,2,0),"")) | G1687: =IF(E1687="","",IFERROR(VLOOKUP(E1687,'Food Catalog'!$A:$C,3,0),"")) | H1687: =IF(E1687="","",IFERROR(VLOOKUP(E1687,'Food Catalog'!$A:$D,4,0),""))
A1688: =IF(I1688="","",TEXT(ROW()-1682,"DIST-0000")) | D1688: =IF(C1688="","",IFERROR(VLOOKUP(C1688,'Partner Pantries'!$A:$B,2,0),"")) | F1688: =IF(E1688="","",IFERROR(VLOOKUP(E1688,'Food Catalog'!$A:$B,2,0),"")) | G1688: =IF(E1688="","",IFERROR(VLOOKUP(E1688,'Food Catalog'!$A:$C,3,0),"")) | H1688: =IF(E1688="","",IFERROR(VLOOKUP(E1688,'Food Catalog'!$A:$D,4,0),""))
A1689: =IF(I1689="","",TEXT(ROW()-1682,"DIST-0000")) | D1689: =IF(C1689="","",IFERROR(VLOOKUP(C1689,'Partner Pantries'!$A:$B,2,0),"")) | F1689: =IF(E1689="","",IFERROR(VLOOKUP(E1689,'Food Catalog'!$A:$B,2,0),"")) | G1689: =IF(E1689="","",IFERROR(VLOOKUP(E1689,'Food Catalog'!$A:$C,3,0),"")) | H1689: =IF(E1689="","",IFERROR(VLOOKUP(E1689,'Food Catalog'!$A:$D,4,0),""))
A1690: =IF(I1690="","",TEXT(ROW()-1682,"DIST-0000")) | D1690: =IF(C1690="","",IFERROR(VLOOKUP(C1690,'Partner Pantries'!$A:$B,2,0),"")) | F1690: =IF(E1690="","",IFERROR(VLOOKUP(E1690,'Food Catalog'!$A:$B,2,0),"")) | G1690: =IF(E1690="","",IFERROR(VLOOKUP(E1690,'Food Catalog'!$A:$C,3,0),"")) | H1690: =IF(E1690="","",IFERROR(VLOOKUP(E1690,'Food Catalog'!$A:$D,4,0),""))
A1691: =IF(I1691="","",TEXT(ROW()-1682,"DIST-0000")) | D1691: =IF(C1691="","",IFERROR(VLOOKUP(C1691,'Partner Pantries'!$A:$B,2,0),"")) | F1691: =IF(E1691="","",IFERROR(VLOOKUP(E1691,'Food Catalog'!$A:$B,2,0),"")) | G1691: =IF(E1691="","",IFERROR(VLOOKUP(E1691,'Food Catalog'!$A:$C,3,0),"")) | H1691: =IF(E1691="","",IFERROR(VLOOKUP(E1691,'Food Catalog'!$A:$D,4,0),""))
A1692: =IF(I1692="","",TEXT(ROW()-1682,"DIST-0000")) | D1692: =IF(C1692="","",IFERROR(VLOOKUP(C1692,'Partner Pantries'!$A:$B,2,0),"")) | F1692: =IF(E1692="","",IFERROR(VLOOKUP(E1692,'Food Catalog'!$A:$B,2,0),"")) | G1692: =IF(E1692="","",IFERROR(VLOOKUP(E1692,'Food Catalog'!$A:$C,3,0),"")) | H1692: =IF(E1692="","",IFERROR(VLOOKUP(E1692,'Food Catalog'!$A:$D,4,0),""))
A1693: =IF(I1693="","",TEXT(ROW()-1682,"DIST-0000")) | D1693: =IF(C1693="","",IFERROR(VLOOKUP(C1693,'Partner Pantries'!$A:$B,2,0),"")) | F1693: =IF(E1693="","",IFERROR(VLOOKUP(E1693,'Food Catalog'!$A:$B,2,0),"")) | G1693: =IF(E1693="","",IFERROR(VLOOKUP(E1693,'Food Catalog'!$A:$C,3,0),"")) | H1693: =IF(E1693="","",IFERROR(VLOOKUP(E1693,'Food Catalog'!$A:$D,4,0),""))
A1694: =IF(I1694="","",TEXT(ROW()-1682,"DIST-0000")) | D1694: =IF(C1694="","",IFERROR(VLOOKUP(C1694,'Partner Pantries'!$A:$B,2,0),"")) | F1694: =IF(E1694="","",IFERROR(VLOOKUP(E1694,'Food Catalog'!$A:$B,2,0),"")) | G1694: =IF(E1694="","",IFERROR(VLOOKUP(E1694,'Food Catalog'!$A:$C,3,0),"")) | H1694: =IF(E1694="","",IFERROR(VLOOKUP(E1694,'Food Catalog'!$A:$D,4,0),""))
A1695: =IF(I1695="","",TEXT(ROW()-1682,"DIST-0000")) | D1695: =IF(C1695="","",IFERROR(VLOOKUP(C1695,'Partner Pantries'!$A:$B,2,0),"")) | F1695: =IF(E1695="","",IFERROR(VLOOKUP(E1695,'Food Catalog'!$A:$B,2,0),"")) | G1695: =IF(E1695="","",IFERROR(VLOOKUP(E1695,'Food Catalog'!$A:$C,3,0),"")) | H1695: =IF(E1695="","",IFERROR(VLOOKUP(E1695,'Food Catalog'!$A:$D,4,0),""))
... A1881: =IF(I1881="","",TEXT(ROW()-1682,"DIST-0000")) | D1881: =IF(C1881="","",IFERROR(VLOOKUP(C1881,'Partner Pantries'!$A:$B,2,0),"")) | F1881: =IF(E1881="","",IFERROR(VLOOKUP(E1881,'Food Catalog'!$A:$B,2,0),"")) | G1881: =IF(E1881="","",IFERROR(VLOOKUP(E1881,'Food Catalog'!$A:$C,3,0),"")) | H1881: =IF(E1881="","",IFERROR(VLOOKUP(E1881,'Food Catalog'!$A:$D,4,0),""))

Sheet Food Catalog
A1: Harvest Hope Community Food Bank | Food Item Catalog
A2: Reference only — do not edit. Item IDs are used by the Donations Log and Distribution History sheets.
A4: Item ID | B4: Item Name | C4: Category | D4: Unit of Measure | E4: Shelf Life (Days) | F4: Priority Level
A5: FI001 | B5: Canned Tuna | C5: Canned Protein | D5: Can (5 oz) | E5: 1095 | F5: High
A6: FI002 | B6: Canned Chicken | C6: Canned Protein | D6: Can (12.5 oz) | E6: 1095 | F6: High
A7: FI003 | B7: Canned Salmon | C7: Canned Protein | D7: Can (14.75 oz) | E7: 1095 | F7: High
A8: FI004 | B8: Canned Black Beans | C8: Canned Protein | D8: Can (15 oz) | E8: 1095 | F8: High
A9: FI005 | B9: Canned Kidney Beans | C9: Canned Protein | D9: Can (15 oz) | E9: 1095 | F9: Medium
A10: FI006 | B10: Canned Chickpeas | C10: Canned Protein | D10: Can (15 oz) | E10: 1095 | F10: Medium
A11: FI007 | B11: Peanut Butter | C11: Canned Protein | D11: Jar (16 oz) | E11: 365 | F11: High
A12: FI008 | B12: Canned Corn | C12: Canned Vegetables | D12: Can (15 oz) | E12: 1095 | F12: Medium
A13: FI009 | B13: Canned Green Beans | C13: Canned Vegetables | D13: Can (14.5 oz) | E13: 1095 | F13: Medium
A14: FI010 | B14: Canned Peas | C14: Canned Vegetables | D14: Can (15 oz) | E14: 1095 | F14: Medium
A15: FI011 | B15: Canned Diced Tomatoes | C15: Canned Vegetables | D15: Can (14.5 oz) | E15: 1095 | F15: Medium
A16: FI012 | B16: Canned Mixed Vegetables | C16: Canned Vegetables | D16: Can (15 oz) | E16: 1095 | F16: Low
... A54: FI050 | B54: Pasta Sauce | C54: Pantry Staples | D54: Jar (24 oz) | E54: 730 | F54: Medium

Sheet Partner Pantries
A1: Harvest Hope Community Food Bank | Partner Pantry Directory
A2: Reference only — do not edit. Pantry IDs are used by the Distribution History sheet.
A4: Pantry ID | B4: Pantry Name | C4: Address | D4: Population Served | E4: Weekly Capacity (Units) | F4: Operating Hours
A5: PP001 | B5: Riverside Community Pantry | C5: 245 River Road | D5: General Families | E5: 500 | F5: Mon/Wed/Fri 9am-2pm
A6: PP002 | B6: St. Augustine's Shelter Pantry | C6: 88 Hope Street | D6: Homeless & Transitional | E6: 200 | F6: Daily 7am-9am
A7: PP003 | B7: Maplewood Senior Center | C7: 1202 Maple Avenue | D7: Elderly (60+) | E7: 150 | F7: Tue/Thu 10am-1pm
A8: PP004 | B8: Oakdale School Family Pantry | C8: 330 School Lane | D8: School-Age Families | E8: 300 | F8: Mon/Thu 3pm-6pm

Sheet Demand Weights
A1: Harvest Hope Community Food Bank | Pantry Demand Weights (Reference)
A2: These weights drive the AI recommendation engine. 1.0 = maximum need, 0.0 = not needed.
A4: Category | B4: PP001 | C4: PP002 | D4: PP003 | E4: PP004 | F4: Best Pantry ID | G4: Best Pantry Name | H4: Best Weight
B5: Riverside Community Pantry | C5: St. Augustine's Shelter Pantry | D5: Maplewood Senior Center | E5: Oakdale School Family Pantry
A6: Baby & Infant | B6: 0.6 | C6: 0.2 | D6: 0 | E6: 0.85 | F6: =INDEX($B$4:$E$4,MATCH(MAX(B6:E6),B6:E6,0)) -> PP004 | G6: =IFERROR(VLOOKUP(F6,'Partner Pantries'!$A:$B,2,0),"") -> Oakdale School Family Pantry | H6: =MAX(B6:E6) -> 0.85
A7: Beverages | B7: 0.7 | C7: 0.9 | D7: 0.8 | E7: 0.85 | F7: =INDEX($B$4:$E$4,MATCH(MAX(B7:E7),B7:E7,0)) -> PP002 | G7: =IFERROR(VLOOKUP(F7,'Partner Pantries'!$A:$B,2,0),"") -> St. Augustine's Shelter Pantry | H7: =MAX(B7:E7) -> 0.9
A8: Bread & Bakery | B8: 0.95 | C8: 1 | D8: 0.9 | E8: 0.9 | F8: =INDEX($B$4:$E$4,MATCH(MAX(B8:E8),B8:E8,0)) -> PP002 | G8: =IFERROR(VLOOKUP(F8,'Partner Pantries'!$A:$B,2,0),"") -> St. Augustine's Shelter Pantry | H8: =MAX(B8:E8) -> 1
A9: Breakfast | B9: 0.8 | C9: 0.9 | D9: 0.85 | E9: 0.95 | F9: =INDEX($B$4:$E$4,MATCH(MAX(B9:E9),B9:E9,0)) -> PP004 | G9: =IFERROR(VLOOKUP(F9,'Partner Pantries'!$A:$B,2,0),"") -> Oakdale School Family Pantry | H9: =MAX(B9:E9) -> 0.95
A10: Canned Fruit | B10: 0.7 | C10: 0.6 | D10: 0.85 | E10: 0.9 | F10: =INDEX($B$4:$E$4,MATCH(MAX(B10:E10),B10:E10,0)) -> PP004 | G10: =IFERROR(VLOOKUP(F10,'Partner Pantries'!$A:$B,2,0),"") -> Oakdale School Family Pantry | H10: =MAX(B10:E10) -> 0.9
A11: Canned Protein | B11: 0.9 | C11: 0.95 | D11: 0.8 | E11: 0.85 | F11: =INDEX($B$4:$E$4,MATCH(MAX(B11:E11),B11:E11,0)) -> PP002 | G11: =IFERROR(VLOOKUP(F11,'Partner Pantries'!$A:$B,2,0),"") -> St. Augustine's Shelter Pantry | H11: =MAX(B11:E11) -> 0.95
A12: Canned Vegetables | B12: 0.8 | C12: 0.7 | D12: 0.9 | E12: 0.8 | F12: =INDEX($B$4:$E$4,MATCH(MAX(B12:E12),B12:E12,0)) -> PP003 | G12: =IFERROR(VLOOKUP(F12,'Partner Pantries'!$A:$B,2,0),"") -> Maplewood Senior Center | H12: =MAX(B12:E12) -> 0.9
A13: Dairy & Refrigerated | B13: 0.9 | C13: 0.7 | D13: 0.85 | E13: 0.95 | F13: =INDEX($B$4:$E$4,MATCH(MAX(B13:E13),B13:E13,0)) -> PP004 | G13: =IFERROR(VLOOKUP(F13,'Partner Pantries'!$A:$B,2,0),"") -> Oakdale School Family Pantry | H13: =MAX(B13:E13) -> 0.95
A14: Dry Goods | B14: 0.9 | C14: 0.85 | D14: 0.7 | E14: 0.9 | F14: =INDEX($B$4:$E$4,MATCH(MAX(B14:E14),B14:E14,0)) -> PP001 | G14: =IFERROR(VLOOKUP(F14,'Partner Pantries'!$A:$B,2,0),"") -> Riverside Community Pantry | H14: =MAX(B14:E14) -> 0.9
A15: Fresh Produce | B15: 0.85 | C15: 0.7 | D15: 0.8 | E15: 0.9 | F15: =INDEX($B$4:$E$4,MATCH(MAX(B15:E15),B15:E15,0)) -> PP004 | G15: =IFERROR(VLOOKUP(F15,'Partner Pantries'!$A:$B,2,0),"") -> Oakdale School Family Pantry | H15: =MAX(B15:E15) -> 0.9
A16: Pantry Staples | B16: 0.8 | C16: 0.75 | D16: 0.7 | E16: 0.75 | F16: =INDEX($B$4:$E$4,MATCH(MAX(B16:E16),B16:E16,0)) -> PP001 | G16: =IFERROR(VLOOKUP(F16,'Partner Pantries'!$A:$B,2,0),"") -> Riverside Community Pantry | H16: =MAX(B16:E16) -> 0.8
A17: Soups & Meals | B17: 0.85 | C17: 0.95 | D17: 0.9 | E17: 0.75 | F17: =INDEX($B$4:$E$4,MATCH(MAX(B17:E17),B17:E17,0)) -> PP002 | G17: =IFERROR(VLOOKUP(F17,'Partner Pantries'!$A:$B,2,0),"") -> St. Augustine's Shelter Pantry | H17: =MAX(B17:E17) -> 0.95
